Workbook

Sheet เริ่มที่นี่
A1: 🏠 home2hatyai — แผนทำเงิน + แผนเก็บเงิน
A2: อ่านแท็บนี้ครั้งเดียว 5 นาที แล้วใช้เวลาแค่ 3 นาที/วัน ตลอดทั้งปี
B4: ⚠️ ความจริงข้อแรก | C4: ไม่มีอะไรที่ 'ผลตอบแทนสูงสุด + ความเสี่ยงต่ำสุด' ในตัวเดียวกัน — นั่นคือกฎของการเงิน ไม่ใช่ความเห็น ใครก็ตามที่เสนอผลตอบแทนการันตี 10-20% ต่อเดือน คือแชร์ลูกโซ่ 100% ให้ปฏิเสธทันทีโดยไม่ต้องคิด สิ่งที่ทำได้จริงคือ 'แยกหน้าที่' — ให้ธุรกิจสร้างผลตอบแทนสูง ให้พอร์ตลงทุนทำหน้าที่ปลอดภัย
B5: ✨ ปาฏิหาริย์ที่มีจริง | C5: ธุรกิจนายหน้าอสังหาฯ ของคุณคือธุรกิจ 'ทุนต่ำ ไม่มีสต๊อก' — ความเสี่ยงถูกจำกัดที่ค่าโฆษณาเท่านั้น ตัวอย่าง: ลงโฆษณา 15,000 บาท/เดือน → ปิดได้ 1 ดีล บ้าน 2.8 ล้าน คอม 3% = 84,000 บาท = ผลตอบแทน 5.6 เท่าของเงินที่เสี่ยง (ROAS 460%) โดยขาดทุนสูงสุดที่เป็นไปได้คือ 15,000 บาท ไม่มีหุ้น ไม่มีคริปโต ไม่มีกองทุนไหนให้แบบนี้ — เพราะมันต้องแลกด้วยฝีมือและแรงของคุณ นั่นคือ 'ขอบ' ของคุณ
B6: 🔧 เครื่องยนต์ 2 ตัว | C6: เครื่องที่ 1 — ธุรกิจ (ผลตอบแทนสูง เสี่ยงจำกัด): ปั่นเงินสดจากค่าคอมมิชชัน วัดผลทุกวัน เครื่องที่ 2 — พอร์ตลงทุน (ผลตอบแทนพอประมาณ เสี่ยงต่ำจริง): รับกำไรจากเครื่องที่ 1 มาเก็บ เงินไหลทางเดียว: ธุรกิจ ➜ พอร์ต ห้ามไหลกลับ (ห้ามถอนพอร์ตมาเติมโฆษณาเด็ดขาด)
B7: 💧 กฎแบ่งเงิน 30/20/30/20 | C7: ทุกบาทที่ได้จากค่าคอมมิชชัน แบ่งทันทีในวันที่ได้รับ ไม่ต้องคิด: 30% → บัญชีภาษี + เงินสำรอง | 20% → เติมกลับเข้าโฆษณา (ขยายธุรกิจ) 30% → พอร์ตลงทุน | 20% → ใช้จ่ายส่วนตัว (ให้รางวัลตัวเอง จะได้ทำต่อได้นาน) แยกบัญชีธนาคาร 4 ใบจริง ๆ — วินัยที่ใช้ 'ระบบ' ชนะวินัยที่ใช้ 'ใจ' เสมอ
B8: ⏱️ ใช้ยังไง — 3 นาที/วัน | C8: 1. เปิดแท็บ 'บันทึกรายวัน' หาแถววันนี้ (ไฮไลต์อัตโนมัติ) กรอกช่องสีเหลือง 8 ช่อง 2. เปิดแท็บ 'แดชบอร์ด' ดูไฟสัญญาณ 3 ดวง — เขียวคือเดินต่อ แดงคือหยุดแก้ก่อนใช้เงินเพิ่ม 3. วันที่ 1 และ 16 ของเดือน: โอนเงินเข้าพอร์ตตามกฎ แล้วบันทึกในแท็บ 'มูลค่าพอร์ตรายวัน' แค่นี้ ไม่ต้องทำอะไรมากกว่านี้ — ความสม่ำเสมอสำคัญกว่าความสมบูรณ์แบบ
B9: 📑 แต่ละแท็บคืออะไร | C9: แดชบอร์ด — สรุปทุกอย่างหน้าเดียว ดูวันนี้ / 7 วัน / 30 วัน / เดือนนี้ บันทึกรายวัน — ที่เดียวที่คุณต้องกรอกทุกวัน (เตรียมวันที่ไว้ให้ 370 วันแล้ว) ดีลในมือ — ท่อการขาย ใส่ลูกค้าทุกคนที่ยังไม่ปิด ระบบคำนวณมูลค่าถ่วงน้ำหนักให้ พอร์ตลงทุน — สินทรัพย์ที่ถืออยู่ + บอกว่าต้องซื้อ/ขายอะไรเพื่อให้ตรงเป้า มูลค่าพอร์ตรายวัน — จดมูลค่าพอร์ต ระบบคำนวณกำไรและ Drawdown ให้ ตั้งค่า — ตัวเลขสมมติฐานทั้งหมด แก้ที่เดียว ทั้งไฟล์เปลี่ยนตาม กฎเหล็ก — 15 กฎกันเจ๊ง อ่านซ้ำทุกต้นเดือน แผน 12 เดือน — เส้นทางเดือนต่อเดือน จากวันนี้ถึงปีหน้า
B10: 🎨 อ่านสียังไง | C10: ช่องสีเหลือง = คุณกรอกเอง | ช่องสีเทา = ระบบคำนวณให้ ห้ามพิมพ์ทับ ตัวเลขสีน้ำเงิน = สมมติฐานที่แก้ได้ | สีเขียว = ดี | สีแดง = ต้องแก้ก่อนใช้เงินเพิ่ม
B11: 📌 ข้อควรทราบ | C11: ตัวเลขตั้งต้นทั้งหมดเป็น 'สมมติฐาน' เพื่อให้เริ่มได้ทันที — ภายใน 30 วันแรก ตัวเลขจริงของคุณ จะเข้ามาแทนที่ และแผนนี้จะกลายเป็นแผนของคุณจริง ๆ ไม่ใช่ของใคร เอกสารนี้เป็นเครื่องมือวางแผนและติดตามผล ไม่ใช่คำแนะนำการลงทุนเฉพาะบุคคล ก่อนซื้อผลิตภัณฑ์การเงินใด ๆ ตรวจสอบใบอนุญาตผู้ขายที่ www.sec.or.th (SEC Check First)

Sheet แดชบอร์ด
A1: 📊 แดชบอร์ด — ดูวันละ 30 วินาที
A2: ทุกตัวเลขคำนวณจากแท็บ 'บันทึกรายวัน' และ 'มูลค่าพอร์ตรายวัน' อัตโนมัติ · ไม่ต้องกรอกอะไรในหน้านี้
A4: 🚦 ไฟสัญญาณ 3 ดวง
A5: ด้าน | B5: สถานะ | G5: ทำอะไรต่อ
A6: 1) เครื่องยนต์ธุรกิจ | B6: =IF(D12=0,"⬜ ยังไม่มีข้อมูล — เริ่มบันทึกก่อน",IF(D22>=3,"🟢 แข็งแรง — เพิ่มงบโฆษณาได้ไม่เกิน 20%",IF(D22>=1.5,"🟡 พอไปได้ — คงงบเดิม ปรับคอนเทนต์ก่อน","🔴 หยุด — อย่าเพิ่งเพิ่มงบ แก้กลุ่มเป้าหมาย/คอนเทนต์ก่อน"))) | G6: วัดจาก ROAS 30 วันล่าสุด
A7: 2) พอร์ตลงทุน | B7: =IF(IFERROR(LOOKUP(2,1/('มูลค่าพอร์ตรายวัน'!$B$4:$B$373<>""),'มูลค่าพอร์ตรายวัน'!$B$4:$B$373),0)=0,"⬜ ยังไม่มีพอร์ต — เริ่มที่เงินสำรองก่อน",IF(IFERROR(LOOKUP(2,1/('มูลค่าพอร์ตรายวัน'!$B$4:$B$373<>""),'มูลค่าพอร์ตรายวัน'!$G$4:$G$373),0)>=-0.05,"🟢 ปกติ — ทำตามแผน DCA ต่อ",IF(IFERROR(LOOKUP(2,1/('มูลค่าพอร์ตรายวัน'!$B$4:$B$373<>""),'มูลค่าพอร์ตรายวัน'!$G$4:$G$373),0)>=-0.15,"🟡 ย่อตัวตามปกติ — ห้ามขาย ซื้อต่อตามแผน","🔴 ตลาดลงแรง — นี่คือช่วงที่ต้องซื้อ ไม่ใช่ขาย"))) | G7: วัดจาก Drawdown ปัจจุบัน
A8: 3) วินัยการบันทึก | B8: =IF(IFERROR(COUNTIFS('บันทึกรายวัน'!$A$4:$A$373,">="&TODAY()-6,'บันทึกรายวัน'!$A$4:$A$373,"<="&TODAY(),'บันทึกรายวัน'!$O$4:$O$373,"✅*")/7,0)>=0.85,"🟢 ยอดเยี่ยม — บันทึกครบเกือบทุกวัน",IF(IFERROR(COUNTIFS('บันทึกรายวัน'!$A$4:$A$373,">="&TODAY()-6,'บันทึกรายวัน'!$A$4:$A$373,"<="&TODAY(),'บันทึกรายวัน'!$O$4:$O$373,"✅*")/7,0)>=0.5,"🟡 ยังขาดบางวัน — ตั้งเตือน 21:00 น.","🔴 ขาดวินัย — แผนดีแค่ไหนก็ไม่ช่วย ถ้าไม่วัดผล")) | G8: นับจาก 7 วันล่าสุดที่สถานะ = ผ่าน
A10: 📈 ตัวชี้วัดหลัก
A11: ตัวชี้วัด | B11: วันนี้ | C11: 7 วันล่าสุด | D11: 30 วันล่าสุด | E11: เดือนนี้ | F11: ตั้งแต่เริ่ม | G11: เป้าหมาย / เกณฑ์
A12: ค่าโฆษณาที่ใช้ (บาท) | B12: =SUMIFS('บันทึกรายวัน'!$B$4:$B$373,'บันทึกรายวัน'!$A$4:$A$373,TODAY()) | C12: =SUMIFS('บันทึกรายวัน'!$B$4:$B$373,'บันทึกรายวัน'!$A$4:$A$373,">="&TODAY()-6,'บันทึกรายวัน'!$A$4:$A$373,"<="&TODAY()) | D12: =SUMIFS('บันทึกรายวัน'!$B$4:$B$373,'บันทึกรายวัน'!$A$4:$A$373,">="&TODAY()-29,'บันทึกรายวัน'!$A$4:$A$373,"<="&TODAY()) | E12: =SUMIFS('บันทึกรายวัน'!$B$4:$B$373,'บันทึกรายวัน'!$A$4:$A$373,">="&EOMONTH(TODAY(),-1)+1,'บันทึกรายวัน'!$A$4:$A$373,"<="&TODAY()) | F12: =SUMIFS('บันทึกรายวัน'!$B$4:$B$373,'บันทึกรายวัน'!$A$4:$A$373,"<="&TODAY())
A13: คนทักเข้ามาใหม่ (คน) | B13: =SUMIFS('บันทึกรายวัน'!$C$4:$C$373,'บันทึกรายวัน'!$A$4:$A$373,TODAY()) | C13: =SUMIFS('บันทึกรายวัน'!$C$4:$C$373,'บันทึกรายวัน'!$A$4:$A$373,">="&TODAY()-6,'บันทึกรายวัน'!$A$4:$A$373,"<="&TODAY()) | D13: =SUMIFS('บันทึกรายวัน'!$C$4:$C$373,'บันทึกรายวัน'!$A$4:$A$373,">="&TODAY()-29,'บันทึกรายวัน'!$A$4:$A$373,"<="&TODAY()) | E13: =SUMIFS('บันทึกรายวัน'!$C$4:$C$373,'บันทึกรายวัน'!$A$4:$A$373,">="&EOMONTH(TODAY(),-1)+1,'บันทึกรายวัน'!$A$4:$A$373,"<="&TODAY()) | F13: =SUMIFS('บันทึกรายวัน'!$C$4:$C$373,'บันทึกรายวัน'!$A$4:$A$373,"<="&TODAY())
A14: lead คุณภาพ (คน) | B14: =SUMIFS('บันทึกรายวัน'!$D$4:$D$373,'บันทึกรายวัน'!$A$4:$A$373,TODAY()) | C14: =SUMIFS('บันทึกรายวัน'!$D$4:$D$373,'บันทึกรายวัน'!$A$4:$A$373,">="&TODAY()-6,'บันทึกรายวัน'!$A$4:$A$373,"<="&TODAY()) | D14: =SUMIFS('บันทึกรายวัน'!$D$4:$D$373,'บันทึกรายวัน'!$A$4:$A$373,">="&TODAY()-29,'บันทึกรายวัน'!$A$4:$A$373,"<="&TODAY()) | E14: =SUMIFS('บันทึกรายวัน'!$D$4:$D$373,'บันทึกรายวัน'!$A$4:$A$373,">="&EOMONTH(TODAY(),-1)+1,'บันทึกรายวัน'!$A$4:$A$373,"<="&TODAY()) | F14: =SUMIFS('บันทึกรายวัน'!$D$4:$D$373,'บันทึกรายวัน'!$A$4:$A$373,"<="&TODAY()) | G14: เป้า/วัน อยู่ในแท็บ ตั้งค่า
A15: นัดดูบ้าน (ครั้ง) | B15: =SUMIFS('บันทึกรายวัน'!$E$4:$E$373,'บันทึกรายวัน'!$A$4:$A$373,TODAY()) | C15: =SUMIFS('บันทึกรายวัน'!$E$4:$E$373,'บันทึกรายวัน'!$A$4:$A$373,">="&TODAY()-6,'บันทึกรายวัน'!$A$4:$A$373,"<="&TODAY()) | D15: =SUMIFS('บันทึกรายวัน'!$E$4:$E$373,'บันทึกรายวัน'!$A$4:$A$373,">="&TODAY()-29,'บันทึกรายวัน'!$A$4:$A$373,"<="&TODAY()) | E15: =SUMIFS('บันทึกรายวัน'!$E$4:$E$373,'บันทึกรายวัน'!$A$4:$A$373,">="&EOMONTH(TODAY(),-1)+1,'บันทึกรายวัน'!$A$4:$A$373,"<="&TODAY()) | F15: =SUMIFS('บันทึกรายวัน'!$E$4:$E$373,'บันทึกรายวัน'!$A$4:$A$373,"<="&TODAY())
A16: ยื่นกู้ (ราย) | B16: =SUMIFS('บันทึกรายวัน'!$F$4:$F$373,'บันทึกรายวัน'!$A$4:$A$373,TODAY()) | C16: =SUMIFS('บันทึกรายวัน'!$F$4:$F$373,'บันทึกรายวัน'!$A$4:$A$373,">="&TODAY()-6,'บันทึกรายวัน'!$A$4:$A$373,"<="&TODAY()) | D16: =SUMIFS('บันทึกรายวัน'!$F$4:$F$373,'บันทึกรายวัน'!$A$4:$A$373,">="&TODAY()-29,'บันทึกรายวัน'!$A$4:$A$373,"<="&TODAY()) | E16: =SUMIFS('บันทึกรายวัน'!$F$4:$F$373,'บันทึกรายวัน'!$A$4:$A$373,">="&EOMONTH(TODAY(),-1)+1,'บันทึกรายวัน'!$A$4:$A$373,"<="&TODAY()) | F16: =SUMIFS('บันทึกรายวัน'!$F$4:$F$373,'บันทึกรายวัน'!$A$4:$A$373,"<="&TODAY())
A17: อนุมัติกู้ (ราย) | B17: =SUMIFS('บันทึกรายวัน'!$G$4:$G$373,'บันทึกรายวัน'!$A$4:$A$373,TODAY()) | C17: =SUMIFS('บันทึกรายวัน'!$G$4:$G$373,'บันทึกรายวัน'!$A$4:$A$373,">="&TODAY()-6,'บันทึกรายวัน'!$A$4:$A$373,"<="&TODAY()) | D17: =SUMIFS('บันทึกรายวัน'!$G$4:$G$373,'บันทึกรายวัน'!$A$4:$A$373,">="&TODAY()-29,'บันทึกรายวัน'!$A$4:$A$373,"<="&TODAY()) | E17: =SUMIFS('บันทึกรายวัน'!$G$4:$G$373,'บันทึกรายวัน'!$A$4:$A$373,">="&EOMONTH(TODAY(),-1)+1,'บันทึกรายวัน'!$A$4:$A$373,"<="&TODAY()) | F17: =SUMIFS('บันทึกรายวัน'!$G$4:$G$373,'บันทึกรายวัน'!$A$4:$A$373,"<="&TODAY())
A18: โอน / ปิดดีล (ดีล) | B18: =SUMIFS('บันทึกรายวัน'!$H$4:$H$373,'บันทึกรายวัน'!$A$4:$A$373,TODAY()) | C18: =SUMIFS('บันทึกรายวัน'!$H$4:$H$373,'บันทึกรายวัน'!$A$4:$A$373,">="&TODAY()-6,'บันทึกรายวัน'!$A$4:$A$373,"<="&TODAY()) | D18: =SUMIFS('บันทึกรายวัน'!$H$4:$H$373,'บันทึกรายวัน'!$A$4:$A$373,">="&TODAY()-29,'บันทึกรายวัน'!$A$4:$A$373,"<="&TODAY()) | E18: =SUMIFS('บันทึกรายวัน'!$H$4:$H$373,'บันทึกรายวัน'!$A$4:$A$373,">="&EOMONTH(TODAY(),-1)+1,'บันทึกรายวัน'!$A$4:$A$373,"<="&TODAY()) | F18: =SUMIFS('บันทึกรายวัน'!$H$4:$H$373,'บันทึกรายวัน'!$A$4:$A$373,"<="&TODAY())
A19: รายได้ค่าคอมที่รับจริง (บาท) | B19: =SUMIFS('บันทึกรายวัน'!$I$4:$I$373,'บันทึกรายวัน'!$A$4:$A$373,TODAY()) | C19: =SUMIFS('บันทึกรายวัน'!$I$4:$I$373,'บันทึกรายวัน'!$A$4:$A$373,">="&TODAY()-6,'บันทึกรายวัน'!$A$4:$A$373,"<="&TODAY()) | D19: =SUMIFS('บันทึกรายวัน'!$I$4:$I$373,'บันทึกรายวัน'!$A$4:$A$373,">="&TODAY()-29,'บันทึกรายวัน'!$A$4:$A$373,"<="&TODAY()) | E19: =SUMIFS('บันทึกรายวัน'!$I$4:$I$373,'บันทึกรายวัน'!$A$4:$A$373,">="&EOMONTH(TODAY(),-1)+1,'บันทึกรายวัน'!$A$4:$A$373,"<="&TODAY()) | F19: =SUMIFS('บันทึกรายวัน'!$I$4:$I$373,'บันทึกรายวัน'!$A$4:$A$373,"<="&TODAY())
A20: กำไรสุทธิ (บาท) | B20: =SUMIFS('บันทึกรายวัน'!$K$4:$K$373,'บันทึกรายวัน'!$A$4:$A$373,TODAY()) | C20: =SUMIFS('บันทึกรายวัน'!$K$4:$K$373,'บันทึกรายวัน'!$A$4:$A$373,">="&TODAY()-6,'บันทึกรายวัน'!$A$4:$A$373,"<="&TODAY()) | D20: =SUMIFS('บันทึกรายวัน'!$K$4:$K$373,'บันทึกรายวัน'!$A$4:$A$373,">="&TODAY()-29,'บันทึกรายวัน'!$A$4:$A$373,"<="&TODAY()) | E20: =SUMIFS('บันทึกรายวัน'!$K$4:$K$373,'บันทึกรายวัน'!$A$4:$A$373,">="&EOMONTH(TODAY(),-1)+1,'บันทึกรายวัน'!$A$4:$A$373,"<="&TODAY()) | F20: =SUMIFS('บันทึกรายวัน'!$K$4:$K$373,'บันทึกรายวัน'!$A$4:$A$373,"<="&TODAY()) | G20: รายได้ − ค่าโฆษณา − ต้นทุนอื่น
A21: CPQL — ค่าโฆษณาต่อ lead คุณภาพ (บาท) | B21: =IFERROR(B12/B14,0) | C21: =IFERROR(C12/C14,0) | D21: =IFERROR(D12/D14,0) | E21: =IFERROR(E12/E14,0) | F21: =IFERROR(F12/F14,0) | G21: ต้องต่ำกว่าเพดานในแท็บ ตั้งค่า
A22: ROAS — รายได้ต่อค่าโฆษณา 1 บาท | B22: =IFERROR(B19/B12,0) | C22: =IFERROR(C19/C12,0) | D22: =IFERROR(D19/D12,0) | E22: =IFERROR(E19/E12,0) | F22: =IFERROR(F19/F12,0) | G22: ≥ 3 เท่า = เพิ่มงบได้ · < 1.5 เท่า = หยุดแก้ก่อน
A23: อัตราปิด: lead คุณภาพ ➜ โอน | B23: =IFERROR(B18/B14,0) | C23: =IFERROR(C18/C14,0) | D23: =IFERROR(D18/D14,0) | E23: =IFERROR(E18/E14,0) | F23: =IFERROR(F18/F14,0) | G23: ตัวเลขจริงของคุณ — เอาไปแก้ในแท็บ ตั้งค่า หลังครบ 30 วัน
A25: 🔻 ท่อการขาย 30 วันล่าสุด — ตรงไหนรั่วมากที่สุด
A26: ทักเข้ามา ➜ lead คุณภาพ | B26: =IFERROR(D14/D13,0) | D26: =IF(D13=0,"ยังไม่มีข้อมูล",D14&" จาก "&D13) | G26: ต่ำกว่า 25% = คอนเทนต์ดึงคนผิดกลุ่ม
A27: lead คุณภาพ ➜ นัดดูบ้าน | B27: =IFERROR(D15/D14,0) | D27: =IF(D14=0,"ยังไม่มีข้อมูล",D15&" จาก "&D14) | G27: ต่ำกว่า 40% = ตอบช้า หรือคัดกรองไม่ตรงงบลูกค้า
A28: นัดดูบ้าน ➜ ยื่นกู้ | B28: =IFERROR(D16/D15,0) | D28: =IF(D15=0,"ยังไม่มีข้อมูล",D16&" จาก "&D15) | G28: ต่ำกว่า 30% = ทรัพย์ไม่ตรงความต้องการ
A29: ยื่นกู้ ➜ อนุมัติ | B29: =IFERROR(D17/D16,0) | D29: =IF(D16=0,"ยังไม่มีข้อมูล",D17&" จาก "&D16) | G29: ต่ำกว่า 50% = ต้องพรีเช็คเครดิตลูกค้าก่อนพาดู
A30: อนุมัติ ➜ โอน | B30: =IFERROR(D18/D17,0) | D30: =IF(D17=0,"ยังไม่มีข้อมูล",D18&" จาก "&D17) | G30: ต่ำกว่า 80% = ปัญหาเอกสาร/ผู้ขาย ต้องตามใกล้ชิด
A32: 🎯 เป้าหมายเดือนนี้
A33: เป้ารายได้ค่าคอมเดือนนี้ (บาท) | B33: ='ตั้งค่า'!$C$17
A34: ทำได้แล้ว (บาท) | B34: =E19
A35: ความคืบหน้า | B35: =IFERROR(E19/'ตั้งค่า'!$C$17,0) | G35: แถบสีเขียวเมื่อถึง 100%
A36: ยังขาดอีก (บาท) | B36: =MAX(0,'ตั้งค่า'!$C$17-E19)
A37: เหลืออีกกี่วันในเดือนนี้ | B37: =EOMONTH(TODAY(),0)-TODAY()
A38: ต้องหา lead คุณภาพอีก (คน) | B38: =MAX(0,ROUND(IFERROR(MAX(0,'ตั้งค่า'!$C$17-E19)/('ตั้งค่า'!$C$8*'ตั้งค่า'!$C$11),0),0)) | G38: คำนวณจากคอมสุทธิต่อดีล x อัตราปิด ในแท็บ ตั้งค่า
A39: งบโฆษณาที่ต้องใช้เพื่อปิดช่องว่าง (บาท) | B39: =MAX(0,ROUND(IFERROR(MAX(0,'ตั้งค่า'!$C$17-E19)/('ตั้งค่า'!$C$8*'ตั้งค่า'!$C$11),0)*'ตั้งค่า'!$C$12,0)) | G39: ถ้าเกินเงินที่มี = ลดเป้า อย่ากู้มาเติม
A41: 🛡️ สุขภาพการเงินและพอร์ตลงทุน
A42: เงินสำรองฉุกเฉินที่มีตอนนี้ (บาท) | B42: =SUMIF('พอร์ตลงทุน'!$A$4:$A$23,0,'พอร์ตลงทุน'!$F$4:$F$23) | G42: =ผลรวมชั้น 0 ในแท็บ พอร์ตลงทุน
A43: เงินสำรองฉุกเฉินเป้าหมาย (บาท) | B43: ='ตั้งค่า'!$C$31
A44: เงินสำรองเต็มแล้วกี่ % | B44: =IFERROR(SUMIF('พอร์ตลงทุน'!$A$4:$A$23,0,'พอร์ตลงทุน'!$F$4:$F$23)/'ตั้งค่า'!$C$31,0) | G44: ต้องถึง 100% ก่อนซื้อสินทรัพย์ชั้น 3
A45: อยู่ได้กี่เดือนถ้ารายได้เป็นศูนย์ | B45: =IFERROR(SUMIF('พอร์ตลงทุน'!$A$4:$A$23,0,'พอร์ตลงทุน'!$F$4:$F$23)/('ตั้งค่า'!$C$29+'ตั้งค่า'!$C$10),0) | G45: ต่ำกว่า 3 เดือน = อันตราย
...

Sheet บันทึกรายวัน
A1: 📅 บันทึกรายวัน — กรอกแค่ช่องสีเหลือง 3 นาที/วัน
A2: แถวของวันนี้จะไฮไลต์สีส้มอัตโนมัติ · ช่องสีเทาคือสูตร ห้ามพิมพ์ทับ · ตัวอย่าง 1 วัน: ค่าโฆษณา 500 | ทักใหม่ 6 | lead คุณภาพ 2 | นัดดู 1 | ยื่นกู้ 0 | อนุมัติ 0 | โอน 0 | รายได้ 0
A3: วันที่ | B3: ค่าโฆษณา (บาท) | C3: ทักใหม่ (คน) | D3: lead คุณภาพ (คน) | E3: นัดดูบ้าน (ครั้ง) | F3: ยื่นกู้ (ราย) | G3: อนุมัติกู้ (ราย) | H3: โอน/ปิดดีล (ดีล) | I3: รายได้รับจริง (บาท) | J3: ต้นทุนอื่น (บาท) | K3: กำไรวันนี้ (บาท) | L3: CPL (บาท/ทัก) | M3: CPQL (บาท/lead) | N3: ควรโอนเข้าพอร์ต (บาท) | O3: สถานะวินัย | P3: หมายเหตุ / บทเรียนวันนี้ | R3: ค่าอ้างอิงอัตโนมัติ — อย่าลบ | S3: ค่า
A4: 46260 | K4: =I4-B4-J4 | L4: =IFERROR(B4/C4,"") | M4: =IFERROR(B4/D4,"") | N4: =ROUND(I4*$S$6,0) | O4: =IF(A4>TODAY(),"—",IF(SUM(B4:J4)=0,"⬜ ยังไม่บันทึก",IF(AND(D4>=$S$4,IFERROR(B4/D4,0)<=$S$5),"✅ ผ่าน","⚠️ ต้องปรับ"))) | R4: เป้า lead คุณภาพ/วัน | S4: ='ตั้งค่า'!$C$20
A5: 46261 | K5: =I5-B5-J5 | L5: =IFERROR(B5/C5,"") | M5: =IFERROR(B5/D5,"") | N5: =ROUND(I5*$S$6,0) | O5: =IF(A5>TODAY(),"—",IF(SUM(B5:J5)=0,"⬜ ยังไม่บันทึก",IF(AND(D5>=$S$4,IFERROR(B5/D5,0)<=$S$5),"✅ ผ่าน","⚠️ ต้องปรับ"))) | R5: เพดาน CPQL (บาท) | S5: ='ตั้งค่า'!$C$14
A6: 46262 | K6: =I6-B6-J6 | L6: =IFERROR(B6/C6,"") | M6: =IFERROR(B6/D6,"") | N6: =ROUND(I6*$S$6,0) | O6: =IF(A6>TODAY(),"—",IF(SUM(B6:J6)=0,"⬜ ยังไม่บันทึก",IF(AND(D6>=$S$4,IFERROR(B6/D6,0)<=$S$5),"✅ ผ่าน","⚠️ ต้องปรับ"))) | R6: % กำไรเข้าพอร์ต | S6: ='ตั้งค่า'!$C$36
A7: 46263 | K7: =I7-B7-J7 | L7: =IFERROR(B7/C7,"") | M7: =IFERROR(B7/D7,"") | N7: =ROUND(I7*$S$6,0) | O7: =IF(A7>TODAY(),"—",IF(SUM(B7:J7)=0,"⬜ ยังไม่บันทึก",IF(AND(D7>=$S$4,IFERROR(B7/D7,0)<=$S$5),"✅ ผ่าน","⚠️ ต้องปรับ")))
A8: 46264 | K8: =I8-B8-J8 | L8: =IFERROR(B8/C8,"") | M8: =IFERROR(B8/D8,"") | N8: =ROUND(I8*$S$6,0) | O8: =IF(A8>TODAY(),"—",IF(SUM(B8:J8)=0,"⬜ ยังไม่บันทึก",IF(AND(D8>=$S$4,IFERROR(B8/D8,0)<=$S$5),"✅ ผ่าน","⚠️ ต้องปรับ")))
A9: 46265 | K9: =I9-B9-J9 | L9: =IFERROR(B9/C9,"") | M9: =IFERROR(B9/D9,"") | N9: =ROUND(I9*$S$6,0) | O9: =IF(A9>TODAY(),"—",IF(SUM(B9:J9)=0,"⬜ ยังไม่บันทึก",IF(AND(D9>=$S$4,IFERROR(B9/D9,0)<=$S$5),"✅ ผ่าน","⚠️ ต้องปรับ")))
A10: 46266 | K10: =I10-B10-J10 | L10: =IFERROR(B10/C10,"") | M10: =IFERROR(B10/D10,"") | N10: =ROUND(I10*$S$6,0) | O10: =IF(A10>TODAY(),"—",IF(SUM(B10:J10)=0,"⬜ ยังไม่บันทึก",IF(AND(D10>=$S$4,IFERROR(B10/D10,0)<=$S$5),"✅ ผ่าน","⚠️ ต้องปรับ")))
A11: 46267 | K11: =I11-B11-J11 | L11: =IFERROR(B11/C11,"") | M11: =IFERROR(B11/D11,"") | N11: =ROUND(I11*$S$6,0) | O11: =IF(A11>TODAY(),"—",IF(SUM(B11:J11)=0,"⬜ ยังไม่บันทึก",IF(AND(D11>=$S$4,IFERROR(B11/D11,0)<=$S$5),"✅ ผ่าน","⚠️ ต้องปรับ")))
A12: 46268 | K12: =I12-B12-J12 | L12: =IFERROR(B12/C12,"") | M12: =IFERROR(B12/D12,"") | N12: =ROUND(I12*$S$6,0) | O12: =IF(A12>TODAY(),"—",IF(SUM(B12:J12)=0,"⬜ ยังไม่บันทึก",IF(AND(D12>=$S$4,IFERROR(B12/D12,0)<=$S$5),"✅ ผ่าน","⚠️ ต้องปรับ")))
A13: 46269 | K13: =I13-B13-J13 | L13: =IFERROR(B13/C13,"") | M13: =IFERROR(B13/D13,"") | N13: =ROUND(I13*$S$6,0) | O13: =IF(A13>TODAY(),"—",IF(SUM(B13:J13)=0,"⬜ ยังไม่บันทึก",IF(AND(D13>=$S$4,IFERROR(B13/D13,0)<=$S$5),"✅ ผ่าน","⚠️ ต้องปรับ")))
A14: 46270 | K14: =I14-B14-J14 | L14: =IFERROR(B14/C14,"") | M14: =IFERROR(B14/D14,"") | N14: =ROUND(I14*$S$6,0) | O14: =IF(A14>TODAY(),"—",IF(SUM(B14:J14)=0,"⬜ ยังไม่บันทึก",IF(AND(D14>=$S$4,IFERROR(B14/D14,0)<=$S$5),"✅ ผ่าน","⚠️ ต้องปรับ")))
A15: 46271 | K15: =I15-B15-J15 | L15: =IFERROR(B15/C15,"") | M15: =IFERROR(B15/D15,"") | N15: =ROUND(I15*$S$6,0) | O15: =IF(A15>TODAY(),"—",IF(SUM(B15:J15)=0,"⬜ ยังไม่บันทึก",IF(AND(D15>=$S$4,IFERROR(B15/D15,0)<=$S$5),"✅ ผ่าน","⚠️ ต้องปรับ")))
A16: 46272 | K16: =I16-B16-J16 | L16: =IFERROR(B16/C16,"") | M16: =IFERROR(B16/D16,"") | N16: =ROUND(I16*$S$6,0) | O16: =IF(A16>TODAY(),"—",IF(SUM(B16:J16)=0,"⬜ ยังไม่บันทึก",IF(AND(D16>=$S$4,IFERROR(B16/D16,0)<=$S$5),"✅ ผ่าน","⚠️ ต้องปรับ")))
A17: 46273 | K17: =I17-B17-J17 | L17: =IFERROR(B17/C17,"") | M17: =IFERROR(B17/D17,"") | N17: =ROUND(I17*$S$6,0) | O17: =IF(A17>TODAY(),"—",IF(SUM(B17:J17)=0,"⬜ ยังไม่บันทึก",IF(AND(D17>=$S$4,IFERROR(B17/D17,0)<=$S$5),"✅ ผ่าน","⚠️ ต้องปรับ")))
A18: 46274 | K18: =I18-B18-J18 | L18: =IFERROR(B18/C18,"") | M18: =IFERROR(B18/D18,"") | N18: =ROUND(I18*$S$6,0) | O18: =IF(A18>TODAY(),"—",IF(SUM(B18:J18)=0,"⬜ ยังไม่บันทึก",IF(AND(D18>=$S$4,IFERROR(B18/D18,0)<=$S$5),"✅ ผ่าน","⚠️ ต้องปรับ")))
... A373: 46629 | K373: =I373-B373-J373 | L373: =IFERROR(B373/C373,"") | M373: =IFERROR(B373/D373,"") | N373: =ROUND(I373*$S$6,0) | O373: =IF(A373>TODAY(),"—",IF(SUM(B373:J373)=0,"⬜ ยังไม่บันทึก",IF(AND(D373>=$S$4,IFERROR(B373/D373,0)<=$S$5),"✅ ผ่าน","⚠️ ต้องปรับ")))

Sheet ดีลในมือ
A1: 📦 ดีลในมือ — ท่อการขาย
A2: ใส่ลูกค้าทุกคนที่ยังไม่ปิด · เลือกสถานะจากเมนู ระบบคำนวณโอกาสสำเร็จและมูลค่าถ่วงน้ำหนักให้ · ตัวอย่างแถว: D001 | คุณเอ | LINE OA | บ้านกลางเมือง ซอย 9 | 2900000 | นัดดูแล้ว | 26/08/2026
A3: สรุปท่อการขาย ณ วันนี้
A4: ดีลที่ยังเปิดอยู่ | B4: =COUNTIFS($F$7:$F$66,"<>",$F$7:$F$66,"<>โอนแล้ว",$F$7:$F$66,"<>หลุด/ปิด") | C4: มูลค่าคอมรวมในท่อ (บาท) | D4: =SUMIFS($H$7:$H$66,$F$7:$F$66,"<>โอนแล้ว",$F$7:$F$66,"<>หลุด/ปิด") | E4: คาดว่าจะได้จริง — ถ่วงน้ำหนัก (บาท) | F4: =SUMIFS($I$7:$I$66,$F$7:$F$66,"<>โอนแล้ว",$F$7:$F$66,"<>หลุด/ปิด") | G4: ปิดได้แล้วรวม (บาท) | H4: =SUMIFS($H$7:$H$66,$F$7:$F$66,"โอนแล้ว")
A6: รหัสดีล | B6: ชื่อลูกค้า | C6: ช่องทางที่มา | D6: ทรัพย์ / โครงการ | E6: ราคาทรัพย์ (บาท) | F6: สถานะ | G6: โอกาส สำเร็จ | H6: คอมคาดหวัง (บาท) | I6: มูลค่าถ่วงน้ำหนัก (บาท) | J6: วันที่เริ่มคุย | K6: คาดว่าจะโอน | L6: อายุดีล (วัน) | M6: ต้องทำอะไรต่อ | N6: อัปเดตล่าสุด | P6: สถานะ | Q6: โอกาส
G7: =IFERROR(INDEX($Q$7:$Q$14,MATCH($F7,$P$7:$P$14,0)),"") | H7: =IF($E7="","",ROUND($E7*'ตั้งค่า'!$C$6*(1-'ตั้งค่า'!$C$7),0)) | I7: =IFERROR(ROUND($H7*$G7,0),"") | K7: =IF($J7="","",$J7+'ตั้งค่า'!$C$15) | L7: =IF($J7="","",TODAY()-$J7) | P7: ทักเข้ามา | Q7: 0.05
G8: =IFERROR(INDEX($Q$7:$Q$14,MATCH($F8,$P$7:$P$14,0)),"") | H8: =IF($E8="","",ROUND($E8*'ตั้งค่า'!$C$6*(1-'ตั้งค่า'!$C$7),0)) | I8: =IFERROR(ROUND($H8*$G8,0),"") | K8: =IF($J8="","",$J8+'ตั้งค่า'!$C$15) | L8: =IF($J8="","",TODAY()-$J8) | P8: คัดกรองแล้ว | Q8: 0.15
G9: =IFERROR(INDEX($Q$7:$Q$14,MATCH($F9,$P$7:$P$14,0)),"") | H9: =IF($E9="","",ROUND($E9*'ตั้งค่า'!$C$6*(1-'ตั้งค่า'!$C$7),0)) | I9: =IFERROR(ROUND($H9*$G9,0),"") | K9: =IF($J9="","",$J9+'ตั้งค่า'!$C$15) | L9: =IF($J9="","",TODAY()-$J9) | P9: นัดดูแล้ว | Q9: 0.3
G10: =IFERROR(INDEX($Q$7:$Q$14,MATCH($F10,$P$7:$P$14,0)),"") | H10: =IF($E10="","",ROUND($E10*'ตั้งค่า'!$C$6*(1-'ตั้งค่า'!$C$7),0)) | I10: =IFERROR(ROUND($H10*$G10,0),"") | K10: =IF($J10="","",$J10+'ตั้งค่า'!$C$15) | L10: =IF($J10="","",TODAY()-$J10) | P10: สนใจจริง | Q10: 0.45
G11: =IFERROR(INDEX($Q$7:$Q$14,MATCH($F11,$P$7:$P$14,0)),"") | H11: =IF($E11="","",ROUND($E11*'ตั้งค่า'!$C$6*(1-'ตั้งค่า'!$C$7),0)) | I11: =IFERROR(ROUND($H11*$G11,0),"") | K11: =IF($J11="","",$J11+'ตั้งค่า'!$C$15) | L11: =IF($J11="","",TODAY()-$J11) | P11: ยื่นกู้แล้ว | Q11: 0.65
G12: =IFERROR(INDEX($Q$7:$Q$14,MATCH($F12,$P$7:$P$14,0)),"") | H12: =IF($E12="","",ROUND($E12*'ตั้งค่า'!$C$6*(1-'ตั้งค่า'!$C$7),0)) | I12: =IFERROR(ROUND($H12*$G12,0),"") | K12: =IF($J12="","",$J12+'ตั้งค่า'!$C$15) | L12: =IF($J12="","",TODAY()-$J12) | P12: อนุมัติแล้ว | Q12: 0.85
G13: =IFERROR(INDEX($Q$7:$Q$14,MATCH($F13,$P$7:$P$14,0)),"") | H13: =IF($E13="","",ROUND($E13*'ตั้งค่า'!$C$6*(1-'ตั้งค่า'!$C$7),0)) | I13: =IFERROR(ROUND($H13*$G13,0),"") | K13: =IF($J13="","",$J13+'ตั้งค่า'!$C$15) | L13: =IF($J13="","",TODAY()-$J13) | P13: โอนแล้ว | Q13: 1
G14: =IFERROR(INDEX($Q$7:$Q$14,MATCH($F14,$P$7:$P$14,0)),"") | H14: =IF($E14="","",ROUND($E14*'ตั้งค่า'!$C$6*(1-'ตั้งค่า'!$C$7),0)) | I14: =IFERROR(ROUND($H14*$G14,0),"") | K14: =IF($J14="","",$J14+'ตั้งค่า'!$C$15) | L14: =IF($J14="","",TODAY()-$J14) | P14: หลุด/ปิด | Q14: 0
G15: =IFERROR(INDEX($Q$7:$Q$14,MATCH($F15,$P$7:$P$14,0)),"") | H15: =IF($E15="","",ROUND($E15*'ตั้งค่า'!$C$6*(1-'ตั้งค่า'!$C$7),0)) | I15: =IFERROR(ROUND($H15*$G15,0),"") | K15: =IF($J15="","",$J15+'ตั้งค่า'!$C$15) | L15: =IF($J15="","",TODAY()-$J15)
G16: =IFERROR(INDEX($Q$7:$Q$14,MATCH($F16,$P$7:$P$14,0)),"") | H16: =IF($E16="","",ROUND($E16*'ตั้งค่า'!$C$6*(1-'ตั้งค่า'!$C$7),0)) | I16: =IFERROR(ROUND($H16*$G16,0),"") | K16: =IF($J16="","",$J16+'ตั้งค่า'!$C$15) | L16: =IF($J16="","",TODAY()-$J16) | P16: เกณฑ์ดีลค้างนาน (วัน) | Q16: =ROUND('ตั้งค่า'!$C$15*1.5,0)
G17: =IFERROR(INDEX($Q$7:$Q$14,MATCH($F17,$P$7:$P$14,0)),"") | H17: =IF($E17="","",ROUND($E17*'ตั้งค่า'!$C$6*(1-'ตั้งค่า'!$C$7),0)) | I17: =IFERROR(ROUND($H17*$G17,0),"") | K17: =IF($J17="","",$J17+'ตั้งค่า'!$C$15) | L17: =IF($J17="","",TODAY()-$J17)
G18: =IFERROR(INDEX($Q$7:$Q$14,MATCH($F18,$P$7:$P$14,0)),"") | H18: =IF($E18="","",ROUND($E18*'ตั้งค่า'!$C$6*(1-'ตั้งค่า'!$C$7),0)) | I18: =IFERROR(ROUND($H18*$G18,0),"") | K18: =IF($J18="","",$J18+'ตั้งค่า'!$C$15) | L18: =IF($J18="","",TODAY()-$J18)
G19: =IFERROR(INDEX($Q$7:$Q$14,MATCH($F19,$P$7:$P$14,0)),"") | H19: =IF($E19="","",ROUND($E19*'ตั้งค่า'!$C$6*(1-'ตั้งค่า'!$C$7),0)) | I19: =IFERROR(ROUND($H19*$G19,0),"") | K19: =IF($J19="","",$J19+'ตั้งค่า'!$C$15) | L19: =IF($J19="","",TODAY()-$J19)
G20: =IFERROR(INDEX($Q$7:$Q$14,MATCH($F20,$P$7:$P$14,0)),"") | H20: =IF($E20="","",ROUND($E20*'ตั้งค่า'!$C$6*(1-'ตั้งค่า'!$C$7),0)) | I20: =IFERROR(ROUND($H20*$G20,0),"") | K20: =IF($J20="","",$J20+'ตั้งค่า'!$C$15) | L20: =IF($J20="","",TODAY()-$J20)
G21: =IFERROR(INDEX($Q$7:$Q$14,MATCH($F21,$P$7:$P$14,0)),"") | H21: =IF($E21="","",ROUND($E21*'ตั้งค่า'!$C$6*(1-'ตั้งค่า'!$C$7),0)) | I21: =IFERROR(ROUND($H21*$G21,0),"") | K21: =IF($J21="","",$J21+'ตั้งค่า'!$C$15) | L21: =IF($J21="","",TODAY()-$J21)
G22: =IFERROR(INDEX($Q$7:$Q$14,MATCH($F22,$P$7:$P$14,0)),"") | H22: =IF($E22="","",ROUND($E22*'ตั้งค่า'!$C$6*(1-'ตั้งค่า'!$C$7),0)) | I22: =IFERROR(ROUND($H22*$G22,0),"") | K22: =IF($J22="","",$J22+'ตั้งค่า'!$C$15) | L22: =IF($J22="","",TODAY()-$J22)
G23: =IFERROR(INDEX($Q$7:$Q$14,MATCH($F23,$P$7:$P$14,0)),"") | H23: =IF($E23="","",ROUND($E23*'ตั้งค่า'!$C$6*(1-'ตั้งค่า'!$C$7),0)) | I23: =IFERROR(ROUND($H23*$G23,0),"") | K23: =IF($J23="","",$J23+'ตั้งค่า'!$C$15) | L23: =IF($J23="","",TODAY()-$J23)
G24: =IFERROR(INDEX($Q$7:$Q$14,MATCH($F24,$P$7:$P$14,0)),"") | H24: =IF($E24="","",ROUND($E24*'ตั้งค่า'!$C$6*(1-'ตั้งค่า'!$C$7),0)) | I24: =IFERROR(ROUND($H24*$G24,0),"") | K24: =IF($J24="","",$J24+'ตั้งค่า'!$C$15) | L24: =IF($J24="","",TODAY()-$J24)
G25: =IFERROR(INDEX($Q$7:$Q$14,MATCH($F25,$P$7:$P$14,0)),"") | H25: =IF($E25="","",ROUND($E25*'ตั้งค่า'!$C$6*(1-'ตั้งค่า'!$C$7),0)) | I25: =IFERROR(ROUND($H25*$G25,0),"") | K25: =IF($J25="","",$J25+'ตั้งค่า'!$C$15) | L25: =IF($J25="","",TODAY()-$J25)
G26: =IFERROR(INDEX($Q$7:$Q$14,MATCH($F26,$P$7:$P$14,0)),"") | H26: =IF($E26="","",ROUND($E26*'ตั้งค่า'!$C$6*(1-'ตั้งค่า'!$C$7),0)) | I26: =IFERROR(ROUND($H26*$G26,0),"") | K26: =IF($J26="","",$J26+'ตั้งค่า'!$C$15) | L26: =IF($J26="","",TODAY()-$J26)
G27: =IFERROR(INDEX($Q$7:$Q$14,MATCH($F27,$P$7:$P$14,0)),"") | H27: =IF($E27="","",ROUND($E27*'ตั้งค่า'!$C$6*(1-'ตั้งค่า'!$C$7),0)) | I27: =IFERROR(ROUND($H27*$G27,0),"") | K27: =IF($J27="","",$J27+'ตั้งค่า'!$C$15) | L27: =IF($J27="","",TODAY()-$J27)
G28: =IFERROR(INDEX($Q$7:$Q$14,MATCH($F28,$P$7:$P$14,0)),"") | H28: =IF($E28="","",ROUND($E28*'ตั้งค่า'!$C$6*(1-'ตั้งค่า'!$C$7),0)) | I28: =IFERROR(ROUND($H28*$G28,0),"") | K28: =IF($J28="","",$J28+'ตั้งค่า'!$C$15) | L28: =IF($J28="","",TODAY()-$J28)
... G66: =IFERROR(INDEX($Q$7:$Q$14,MATCH($F66,$P$7:$P$14,0)),"") | H66: =IF($E66="","",ROUND($E66*'ตั้งค่า'!$C$6*(1-'ตั้งค่า'!$C$7),0)) | I66: =IFERROR(ROUND($H66*$G66,0),"") | K66: =IF($J66="","",$J66+'ตั้งค่า'!$C$15) | L66: =IF($J66="","",TODAY()-$J66)

Sheet พอร์ตลงทุน
A1: 💰 พอร์ตลงทุน — ชั้นความเสี่ยง 0-4
A2: แถว 4-13 คือ 'เมนูสินทรัพย์' ที่เตรียมไว้ให้ (ยอดเป็น 0 อยู่) — ใส่ยอดจริงลงไป หรือลบทิ้งแล้วพิมพ์ของคุณเอง · ชั้น 0 = เงินสำรองฉุกเฉิน ต้องเต็มก่อนถึงจะขึ้นชั้น 3 ได้
A3: ชั้น | B3: ชื่อสินทรัพย์ | C3: ประเภท | D3: ระดับความเสี่ยง | E3: เงินต้นที่ลง (บาท) | F3: มูลค่าปัจจุบัน (บาท) | G3: กำไร/ขาดทุน (บาท) | H3: % กำไร | I3: % ของพอร์ต | J3: ผลตอบแทน คาดหวัง/ปี | K3: หมายเหตุ / ข้อควรระวัง
A4: 0 | B4: บัญชีเงินฝากดอกเบี้ยสูง / e-Savings | C4: เงินสด | D4: ต่ำมาก | E4: 0 | F4: 0 | G4: =IF($F4="","",$F4-$E4) | H4: =IFERROR($G4/$E4,"") | I4: =IFERROR($F4/$F$24,"") | J4: 0.015 | K4: เงินสำรองฉุกเฉิน ถอนได้ทันที · เลือกธนาคารในความคุ้มครองของสถาบันคุ้มครองเงินฝาก
A5: 0 | B5: กองทุนตลาดเงิน (Money Market) | C5: กองทุนรวม | D5: ต่ำมาก | E5: 0 | F5: 0 | G5: =IF($F5="","",$F5-$E5) | H5: =IFERROR($G5/$E5,"") | I5: =IFERROR($F5/$F$24,"") | J5: 0.018 | K5: สภาพคล่องสูง ขายได้เงินวันทำการถัดไป · ใช้พักเงินก้อนที่รอโอกาส
A6: 1 | B6: พันธบัตรออมทรัพย์รัฐบาล | C6: ตราสารหนี้ภาครัฐ | D6: ต่ำมาก | E6: 0 | F6: 0 | G6: =IF($F6="","",$F6-$E6) | H6: =IFERROR($G6/$E6,"") | I6: =IFERROR($F6/$F$24,"") | J6: 0.025 | K6: ความเสี่ยงต่ำที่สุดในประเทศ · เปิดขายเป็นรอบ ซื้อผ่านแอปธนาคารตัวแทน
A7: 1 | B7: กองทุนตราสารหนี้ระยะสั้น | C7: กองทุนรวม | D7: ต่ำ | E7: 0 | F7: 0 | G7: =IF($F7="","",$F7-$E7) | H7: =IFERROR($G7/$E7,"") | I7: =IFERROR($F7/$F$24,"") | J7: 0.022 | K7: เลือกกองที่ค่าธรรมเนียมต่ำ · ค่าธรรมเนียมคือสิ่งเดียวที่คุณควบคุมได้ 100%
A8: 2 | B8: หุ้นกู้เอกชนเรตติ้ง A ขึ้นไป | C8: ตราสารหนี้เอกชน | D8: ปานกลาง | E8: 0 | F8: 0 | G8: =IF($F8="","",$F8-$E8) | H8: =IFERROR($G8/$E8,"") | I8: =IFERROR($F8/$F$24,"") | J8: 0.045 | K8: ห้ามซื้อหุ้นกู้ไม่มีเรตติ้ง หรือ High Yield เด็ดขาด · กระจายอย่างน้อย 5 บริษัท
A9: 2 | B9: กองทุนอสังหาฯ / โครงสร้างพื้นฐาน (REIT, Infra) | C9: กองทุนรวม | D9: ปานกลาง | E9: 0 | F9: 0 | G9: =IF($F9="","",$F9-$E9) | H9: =IFERROR($G9/$E9,"") | I9: =IFERROR($F9/$F$24,"") | J9: 0.055 | K9: ปันผลสม่ำเสมอ และเป็นสายที่คุณเข้าใจดีอยู่แล้วจากงานอสังหาฯ
A10: 3 | B10: กองทุนดัชนีหุ้นโลก (MSCI World / S&P 500) | C10: กองทุนรวม | D10: สูง | E10: 0 | F10: 0 | G10: =IF($F10="","",$F10-$E10) | H10: =IFERROR($G10/$E10,"") | I10: =IFERROR($F10/$F$24,"") | J10: 0.075 | K10: ทยอยซื้อทุกวันที่ 1 เท่านั้น · ห้ามลงครั้งเดียวทั้งก้อน · ติดลบ 30% ถือเป็นเรื่องปกติ
A11: 3 | B11: กองทุนดัชนีหุ้นไทย (SET50) | C11: กองทุนรวม | D11: สูง | E11: 0 | F11: 0 | G11: =IF($F11="","",$F11-$E11) | H11: =IFERROR($G11/$E11,"") | I11: =IFERROR($F11/$F$24,"") | J11: 0.06 | K11: สัดส่วนไม่ควรเกินครึ่งของชั้น 3 · อย่ากระจุกในประเทศเดียวกับที่คุณทำมาหากิน
A12: 4 | B12: กองทุน Thai ESG | C12: กองทุนลดหย่อนภาษี | D12: ปานกลาง-สูง | E12: 0 | F12: 0 | G12: =IF($F12="","",$F12-$E12) | H12: =IFERROR($G12/$E12,"") | I12: =IFERROR($F12/$F$24,"") | J12: 0.07 | K12: ลดหย่อนภาษีได้ = ผลตอบแทนแน่นอนเท่าฐานภาษีคุณในปีแรก · ตรวจเงื่อนไข/วงเงินล่าสุดที่ rd.go.th
A13: 4 | B13: SSF / RMF | C13: กองทุนลดหย่อนภาษี | D13: ปรับได้ | E13: 0 | F13: 0 | G13: =IF($F13="","",$F13-$E13) | H13: =IFERROR($G13/$E13,"") | I13: =IFERROR($F13/$F$24,"") | J13: 0.07 | K13: RMF ต้องถือถึงอายุ 55 ปี · เลือกนโยบายกองให้เติมเต็มชั้นที่ยังขาด
G14: =IF($F14="","",$F14-$E14) | H14: =IFERROR($G14/$E14,"") | I14: =IFERROR($F14/$F$24,"")
G15: =IF($F15="","",$F15-$E15) | H15: =IFERROR($G15/$E15,"") | I15: =IFERROR($F15/$F$24,"")
G16: =IF($F16="","",$F16-$E16) | H16: =IFERROR($G16/$E16,"") | I16: =IFERROR($F16/$F$24,"")
G17: =IF($F17="","",$F17-$E17) | H17: =IFERROR($G17/$E17,"") | I17: =IFERROR($F17/$F$24,"")
G18: =IF($F18="","",$F18-$E18) | H18: =IFERROR($G18/$E18,"") | I18: =IFERROR($F18/$F$24,"")
G19: =IF($F19="","",$F19-$E19) | H19: =IFERROR($G19/$E19,"") | I19: =IFERROR($F19/$F$24,"")
G20: =IF($F20="","",$F20-$E20) | H20: =IFERROR($G20/$E20,"") | I20: =IFERROR($F20/$F$24,"")
G21: =IF($F21="","",$F21-$E21) | H21: =IFERROR($G21/$E21,"") | I21: =IFERROR($F21/$F$24,"")
G22: =IF($F22="","",$F22-$E22) | H22: =IFERROR($G22/$E22,"") | I22: =IFERROR($F22/$F$24,"")
G23: =IF($F23="","",$F23-$E23) | H23: =IFERROR($G23/$E23,"") | I23: =IFERROR($F23/$F$24,"")
A24: รวม | B24: พอร์ตทั้งหมด | E24: =SUM(E4:E23) | F24: =SUM(F4:F23) | G24: =F24-E24 | H24: =IFERROR(G24/E24,"") | I24: =IFERROR(F24/F24,"") | J24: =IFERROR(SUMPRODUCT($F$4:$F$23,$J$4:$J$23)/$F$24,0) | K24: ผลตอบแทนคาดหวังถ่วงน้ำหนักของพอร์ตจริง
A26: ⚖️ ต้องซื้อ/ขายอะไรบ้างให้ตรงเป้า (Rebalance)
A27: ชั้น | B27: ชื่อชั้น | C27: มูลค่าตอนนี้ (บาท) | D27: % จริง | E27: เป้าหมาย (บาท) | F27: ส่วนต่าง (บาท) | G27: ต้องทำอะไร
A28: 0 | B28: เงินสำรองฉุกเฉิน (เงินสด) | C28: =SUMIF($A$4:$A$23,0,$F$4:$F$23) | D28: =IFERROR(C28/$C$33,"") | E28: ='ตั้งค่า'!$C$31 | F28: =E28-C28 | G28: =IF(F28>1000,"➕ เติมอีก "&TEXT(F28,"#,##0")&" บาท",IF(F28<-1000,"➖ เกินเป้า "&TEXT(-F28,"#,##0")&" บาท","✅ พอดีแล้ว"))
A29: 1 | B29: ปลอดภัย — พันธบัตร/ตราสารหนี้ | C29: =SUMIF($A$4:$A$23,1,$F$4:$F$23) | D29: =IFERROR(C29/$C$33,"") | E29: =MAX(0,$C$33-$E$28)*'ตั้งค่า'!$C$40 | F29: =E29-C29 | G29: =IF(F29>1000,"➕ เติมอีก "&TEXT(F29,"#,##0")&" บาท",IF(F29<-1000,"➖ เกินเป้า "&TEXT(-F29,"#,##0")&" บาท","✅ พอดีแล้ว"))
A30: 2 | B30: รายได้ประจำ — หุ้นกู้/REIT | C30: =SUMIF($A$4:$A$23,2,$F$4:$F$23) | D30: =IFERROR(C30/$C$33,"") | E30: =MAX(0,$C$33-$E$28)*'ตั้งค่า'!$C$41 | F30: =E30-C30 | G30: =IF(F30>1000,"➕ เติมอีก "&TEXT(F30,"#,##0")&" บาท",IF(F30<-1000,"➖ เกินเป้า "&TEXT(-F30,"#,##0")&" บาท","✅ พอดีแล้ว"))
A31: 3 | B31: เติบโต — กองดัชนีหุ้น (DCA) | C31: =SUMIF($A$4:$A$23,3,$F$4:$F$23) | D31: =IFERROR(C31/$C$33,"") | E31: =MAX(0,$C$33-$E$28)*'ตั้งค่า'!$C$42 | F31: =E31-C31 | G31: =IF(F31>1000,"➕ เติมอีก "&TEXT(F31,"#,##0")&" บาท",IF(F31<-1000,"➖ เกินเป้า "&TEXT(-F31,"#,##0")&" บาท","✅ พอดีแล้ว"))
A32: 4 | B32: ลดหย่อนภาษี — Thai ESG/SSF/RMF | C32: =SUMIF($A$4:$A$23,4,$F$4:$F$23) | D32: =IFERROR(C32/$C$33,"") | E32: =MAX(0,$C$33-$E$28)*'ตั้งค่า'!$C$43 | F32: =E32-C32 | G32: =IF(F32>1000,"➕ เติมอีก "&TEXT(F32,"#,##0")&" บาท",IF(F32<-1000,"➖ เกินเป้า "&TEXT(-F32,"#,##0")&" บาท","✅ พอดีแล้ว"))
B33: รวมทุกชั้น | C33: =SUM(C28:C32)

Sheet มูลค่าพอร์ตรายวัน
A1: 📈 มูลค่าพอร์ตรายวัน
A2: กรอกแค่ 2 ช่อง: มูลค่าพอร์ตรวม กับ เงินที่เติมเข้าวันนี้ · ไม่ต้องกรอกครบทุกวันก็ได้ แต่ต้องกรอกทุกวันที่ 1 และ 16 · ตัวอย่างวันแรก: มูลค่าพอร์ตรวม 100,000 | เติมเข้าวันนี้ 100,000
A3: วันที่ | B3: มูลค่าพอร์ตรวม (บาท) | C3: เติมเข้าวันนี้ (บาท) | D3: เงินต้นสะสม (บาท) | E3: กำไร/ขาดทุนสะสม (บาท) | F3: จุดสูงสุด (บาท) | G3: Drawdown | H3: หมายเหตุ
A4: 46260 | D4: =IF($B4="","",SUM($C$4:$C4)) | E4: =IF($B4="","",$B4-$D4) | F4: =IF($B4="","",MAX($B$4:$B4)) | G4: =IF($B4="","",IFERROR($B4/MAX($B$4:$B4)-1,0))
A5: 46261 | D5: =IF($B5="","",SUM($C$4:$C5)) | E5: =IF($B5="","",$B5-$D5) | F5: =IF($B5="","",MAX($B$4:$B5)) | G5: =IF($B5="","",IFERROR($B5/MAX($B$4:$B5)-1,0))
A6: 46262 | D6: =IF($B6="","",SUM($C$4:$C6)) | E6: =IF($B6="","",$B6-$D6) | F6: =IF($B6="","",MAX($B$4:$B6)) | G6: =IF($B6="","",IFERROR($B6/MAX($B$4:$B6)-1,0))
A7: 46263 | D7: =IF($B7="","",SUM($C$4:$C7)) | E7: =IF($B7="","",$B7-$D7) | F7: =IF($B7="","",MAX($B$4:$B7)) | G7: =IF($B7="","",IFERROR($B7/MAX($B$4:$B7)-1,0))
A8: 46264 | D8: =IF($B8="","",SUM($C$4:$C8)) | E8: =IF($B8="","",$B8-$D8) | F8: =IF($B8="","",MAX($B$4:$B8)) | G8: =IF($B8="","",IFERROR($B8/MAX($B$4:$B8)-1,0))
A9: 46265 | D9: =IF($B9="","",SUM($C$4:$C9)) | E9: =IF($B9="","",$B9-$D9) | F9: =IF($B9="","",MAX($B$4:$B9)) | G9: =IF($B9="","",IFERROR($B9/MAX($B$4:$B9)-1,0))
A10: 46266 | D10: =IF($B10="","",SUM($C$4:$C10)) | E10: =IF($B10="","",$B10-$D10) | F10: =IF($B10="","",MAX($B$4:$B10)) | G10: =IF($B10="","",IFERROR($B10/MAX($B$4:$B10)-1,0))
A11: 46267 | D11: =IF($B11="","",SUM($C$4:$C11)) | E11: =IF($B11="","",$B11-$D11) | F11: =IF($B11="","",MAX($B$4:$B11)) | G11: =IF($B11="","",IFERROR($B11/MAX($B$4:$B11)-1,0))
A12: 46268 | D12: =IF($B12="","",SUM($C$4:$C12)) | E12: =IF($B12="","",$B12-$D12) | F12: =IF($B12="","",MAX($B$4:$B12)) | G12: =IF($B12="","",IFERROR($B12/MAX($B$4:$B12)-1,0))
A13: 46269 | D13: =IF($B13="","",SUM($C$4:$C13)) | E13: =IF($B13="","",$B13-$D13) | F13: =IF($B13="","",MAX($B$4:$B13)) | G13: =IF($B13="","",IFERROR($B13/MAX($B$4:$B13)-1,0))
A14: 46270 | D14: =IF($B14="","",SUM($C$4:$C14)) | E14: =IF($B14="","",$B14-$D14) | F14: =IF($B14="","",MAX($B$4:$B14)) | G14: =IF($B14="","",IFERROR($B14/MAX($B$4:$B14)-1,0))
A15: 46271 | D15: =IF($B15="","",SUM($C$4:$C15)) | E15: =IF($B15="","",$B15-$D15) | F15: =IF($B15="","",MAX($B$4:$B15)) | G15: =IF($B15="","",IFERROR($B15/MAX($B$4:$B15)-1,0))
... A373: 46629 | D373: =IF($B373="","",SUM($C$4:$C373)) | E373: =IF($B373="","",$B373-$D373) | F373: =IF($B373="","",MAX($B$4:$B373)) | G373: =IF($B373="","",IFERROR($B373/MAX($B$4:$B373)-1,0))

Sheet ตั้งค่า
A1: ⚙️ ตั้งค่าและสมมติฐาน
A2: แก้เฉพาะช่องสีเหลือง (ตัวเลขสีน้ำเงิน) — ช่องสีเทาคือสูตรคำนวณ ห้ามพิมพ์ทับ · ตัวอย่างการกรอก: ราคาทรัพย์เฉลี่ย = 2800000 , ค่าคอม = 0.03 (หมายถึง 3%)
B4: 1 · ตัวเลขธุรกิจ (นายหน้า / lead-gen อสังหาฯ หาดใหญ่)
B5: ราคาทรัพย์เฉลี่ยต่อดีล (บาท) | C5: 2800000 | D5: ราคาบ้าน/ทาวน์โฮมที่คุณปิดได้บ่อยที่สุดในหาดใหญ่
B6: อัตราค่าคอมมิชชันที่ได้รับ (%) | C6: 0.03 | D6: ขายบ้านมือสอง 3% · โครงการจัดสรรมักได้ 2-3% · เช่า 1 เดือน
B7: ส่วนแบ่งให้ co-agent / ทีม (%) | C7: 0 | D7: ถ้าแบ่งครึ่งกับนายหน้าอีกฝั่ง ใส่ 0.50
B8: ➜ คอมมิชชันสุทธิต่อ 1 ดีล (บาท) | C8: =$C$5*$C$6*(1-$C$7) | D8: คำนวณอัตโนมัติ
B9: งบโฆษณาต่อวัน (บาท) | C9: 500 | D9: เงินก้อนเดียวที่คุณเสี่ยงจริง ๆ — ขาดทุนสูงสุดต่อเดือนคือตัวเลขนี้ x30
B10: ต้นทุนคงที่ต่อเดือน (บาท) | C10: 15000 | D10: ค่าน้ำมัน ค่าเน็ต ค่าเครื่องมือ ค่าจ้างแอดมิน ค่าเซิร์ฟเวอร์ LINE bot
B11: อัตราปิด: lead คุณภาพ ➜ โอน (%) | C11: 0.03 | D11: เริ่มที่ 3% ถ้ายังไม่รู้ตัวเลขจริง · แก้เป็นของจริงหลังครบ 30 วัน
B12: CPQL จริง — ค่าโฆษณาต่อ lead คุณภาพ 1 คน (บาท) | C12: 400 | D12: แดชบอร์ดจะบอกตัวเลขจริงให้หลังบันทึกไป 7 วัน
B13: ➜ มูลค่าของ lead คุณภาพ 1 คน (บาท) | C13: =$C$8*$C$11 | D13: คอมสุทธิ x อัตราปิด = เงินที่ lead 1 คนมีค่าเฉลี่ย
B14: ➜ เพดาน CPQL ที่ยอมจ่ายได้ (บาท) | C14: =$C$13*0.25 | D14: จ่ายไม่เกิน 25% ของมูลค่า lead · เกินเพดาน = หยุดแอดทันที
B15: จำนวนวันเฉลี่ย: lead ➜ โอนเงิน | C15: 75 | D15: อสังหาฯ ไทยใช้เวลายื่นกู้+โอนราว 60-90 วัน — วางแผนเงินสดเผื่อไว้
B16: 2 · เป้าหมายและผลที่คาดว่าจะได้
B17: เป้ารายได้ค่าคอมต่อเดือน (บาท) | C17: 150000 | D17: ตั้งให้ท้าทายแต่เป็นไปได้
B18: ➜ ต้องปิดกี่ดีลต่อเดือน | C18: =IFERROR($C$17/$C$8,0)
B19: ➜ ต้องมี lead คุณภาพกี่คนต่อเดือน | C19: =IFERROR($C$18/$C$11,0)
B20: ➜ ต้องมี lead คุณภาพกี่คนต่อวัน | C20: =IFERROR($C$19/30,0) | D20: ตัวเลขนี้คือ KPI เดียวที่ต้องดูทุกวัน
B21: ➜ งบโฆษณาต่อเดือน (บาท) | C21: =$C$9*30
B22: ➜ lead คุณภาพที่งบนี้ควรได้ (คน/เดือน) | C22: =IFERROR($C$21/$C$12,0)
B23: ➜ รายได้ที่คาดว่าจะได้ (บาท/เดือน) | C23: =IFERROR($C$22*$C$11*$C$8,0)
B24: ➜ กำไรสุทธิที่คาดว่าจะได้ (บาท/เดือน) | C24: =$C$23-$C$21-$C$10 | D24: หักค่าโฆษณาและต้นทุนคงที่แล้ว
B25: ➜ ROAS — ได้กี่เท่าของค่าโฆษณา | C25: =IFERROR($C$23/$C$21,0) | D25: ต่ำกว่า 2 เท่า = ยังไม่ควรเพิ่มงบ
B26: ➜ งบโฆษณาที่ควรใช้เพื่อถึงเป้า (บาท/เดือน) | C26: =IFERROR($C$19*$C$12,0) | D26: ถ้าตัวเลขนี้สูงกว่างบจริงมาก แปลว่าเป้าสูงเกินกำลังทุน
B27: 3 · การเงินส่วนตัวและเงินสำรอง
B28: ทุนตั้งต้นที่มีตอนนี้ (บาท) | C28: 100000 | D28: เงินเย็นที่ไม่ต้องใช้ใน 12 เดือน
B29: รายจ่ายจำเป็นส่วนตัวต่อเดือน (บาท) | C29: 25000 | D29: ค่ากิน ค่าผ่อน ค่าเทอม ค่ารักษา
B30: จำนวนเดือนที่ต้องมีเงินสำรอง | C30: 6 | D30: อาชีพรายได้ไม่แน่นอนอย่างนายหน้า ควร 6-12 เดือน
B31: ➜ เงินสำรองฉุกเฉินเป้าหมาย (บาท) | C31: =($C$29+$C$10)*$C$30 | D31: ต้องเต็มก้อนนี้ก่อน ถึงจะซื้อสินทรัพย์เสี่ยงได้
B32: ฐานภาษีเงินได้สูงสุดของคุณ (%) | C32: 0.2 | D32: ใช้คำนวณผลตอบแทนจากกองลดหย่อนภาษี · ดูขั้นบันไดที่ rd.go.th
B33: 4 · กฎแบ่งเงิน — ทุกบาทที่ได้รับ แบ่งทันที
B34: % เข้าบัญชีภาษี + เงินสำรอง | C34: 0.3 | D34: นายหน้าถูกหัก ณ ที่จ่าย 3-5% แต่ต้องยื่นเพิ่มตอนปลายปี กันไว้ก่อนปลอดภัยกว่า
B35: % เติมกลับเข้าโฆษณา (ขยายธุรกิจ) | C35: 0.2 | D35: ส่วนที่ทำให้เดือนหน้าโตกว่าเดือนนี้
B36: % เข้าพอร์ตลงทุน | C36: 0.3 | D36: ส่วนที่ทำให้คุณรวยแม้วันที่ไม่ได้ทำงาน
B37: % ใช้จ่ายส่วนตัว | C37: 0.2 | D37: ต้องมี ไม่งั้นทำได้ไม่เกิน 6 เดือนแล้วเลิก
B38: ➜ รวม (ต้องได้ 100%) | C38: =$C$34+$C$35+$C$36+$C$37 | D38: ถ้าไม่ใช่ 100% ให้กลับไปแก้ 4 ช่องบน
B39: 5 · สัดส่วนพอร์ตลงทุนเป้าหมาย (ของเงินที่เหลือหลังกันเงินสำรองแล้ว)
B40: ชั้น 1 · ปลอดภัย (พันธบัตร / กองตราสารหนี้ / ฝากดอกสูง) | C40: 0.4 | D40: แทบไม่ขาดทุน · คาดหวัง 1.5-3% ต่อปี
B41: ชั้น 2 · รายได้ประจำ (หุ้นกู้เรตติ้งดี / REIT / กองปันผล) | C41: 0.25 | D41: ผันผวนน้อย มีกระแสเงินสด · คาดหวัง 4-6% ต่อปี
...

Sheet กฎเหล็ก
A1: 🚦 กฎเหล็ก 15 ข้อ — อ่านซ้ำทุกวันที่ 1 ของเดือน
A2: กฎพวกนี้คือสิ่งที่ทำให้ 'ความเสี่ยงต่ำ' เป็นจริง — ไม่ใช่การเลือกสินทรัพย์ · คนส่วนใหญ่ไม่ได้เจ๊งเพราะเลือกกองผิด แต่เจ๊งเพราะทำผิดกฎพวกนี้
A3: ข้อ | B3: กฎ | C3: ทำไมต้องมีกฎนี้ | D3: สถานะ
A4: 1 | B4: ห้ามลงทุนด้วยเงินที่ต้องใช้ภายใน 12 เดือน | C4: การถูกบังคับให้ขายตอนตลาดลง คือสาเหตุอันดับ 1 ของการขาดทุนถาวร | D4: ⬜ ยังไม่ทำ
A5: 2 | B5: เงินสำรอง 6 เดือนต้องเต็มก่อน จึงจะซื้อสินทรัพย์ชั้น 3 ได้ | C5: รายได้นายหน้าไม่สม่ำเสมอ · เงินสำรองคือสิ่งที่ทำให้คุณไม่ต้องขายของถูก | D5: ⬜ ยังไม่ทำ
A6: 3 | B6: ห้ามใช้เงินกู้ บัตรเครดิต หรือมาร์จิ้น มาลงทุนหรือมาเติมค่าโฆษณา | C6: หนี้เปลี่ยนการขาดทุนชั่วคราวให้กลายเป็นการล้มละลายถาวร | D6: ⬜ ยังไม่ทำ
A7: 4 | B7: ห้ามใส่เงินเกิน 10% ของพอร์ตในสินทรัพย์ตัวเดียว (ยกเว้นชั้น 0-1) | C7: บริษัทเดียวล้มได้ · ตลาดทั้งตลาดล้มยากกว่ามาก | D7: ⬜ ยังไม่ทำ
A8: 5 | B8: เพิ่มงบโฆษณาได้เฉพาะเมื่อ ROAS 30 วัน ≥ 3 เท่า และเพิ่มครั้งละไม่เกิน 20% | C8: การเพิ่มงบตอนตัวเลขยังไม่นิ่ง คือการเร่งเผาเงินให้เร็วขึ้น | D8: ⬜ ยังไม่ทำ
A9: 6 | B9: ถ้า CPQL 7 วันเกินเพดาน 2 วันติด ให้หยุดแอด แล้วแก้คอนเทนต์/กลุ่มเป้าหมายก่อน | C9: เพดานคือเบรกที่คำนวณจากกำไรจริง ไม่ใช่ความรู้สึก | D9: ⬜ ยังไม่ทำ
A10: 7 | B10: ห้ามซื้อ-ขายตามข่าว กลุ่มไลน์ หรือคนแนะนำ — ซื้อตามแผน DCA เท่านั้น | C10: การจับจังหวะตลาดแพ้ DCA ในระยะยาวเกือบทุกกรณี และกินเวลาสมองที่ควรใช้กับธุรกิจ | D10: ⬜ ยังไม่ทำ
A11: 8 | B11: Rebalance ปีละ 2 ครั้ง (มิ.ย. และ ธ.ค.) หรือเมื่อชั้นใดเบี่ยงเกิน 5% | C11: บังคับให้ 'ขายของที่ขึ้น ซื้อของที่ลง' โดยอัตโนมัติ โดยไม่ต้องใช้อารมณ์ | D11: ⬜ ยังไม่ทำ
A12: 9 | B12: อะไรที่การันตีผลตอบแทนเกิน 10% ต่อเดือน = แชร์ลูกโซ่ 100% ปฏิเสธทันที | C12: ไม่มีข้อยกเว้น ไม่มี 'รอบนี้พิเศษ' · ตรวจใบอนุญาตที่ SEC Check First ก่อนโอนเงินทุกครั้ง | D12: ⬜ ยังไม่ทำ
A13: 10 | B13: บันทึกตัวเลขทุกวันก่อน 21:00 น. ไม่มีข้อยกเว้น | C13: สิ่งที่ไม่ได้วัด จะไม่มีทางดีขึ้น · 3 นาที/วัน คือราคาที่ถูกที่สุดของความสำเร็จ | D13: ⬜ ยังไม่ทำ
A14: 11 | B14: โอนกำไรเข้าพอร์ตทุกวันที่ 1 และ 16 — ก่อนใช้จ่ายอย่างอื่น | C14: จ่ายให้ตัวเองก่อนเสมอ · เงินที่เหลือค่อยใช้ ไม่ใช่ใช้แล้วค่อยเหลือ | D14: ⬜ ยังไม่ทำ
A15: 12 | B15: แยกบัญชีธนาคาร 4 ใบจริง: ธุรกิจ / ภาษี+สำรอง / ลงทุน / ใช้จ่าย | C15: ระบบชนะวินัย · ถ้าเงินอยู่กองเดียวกัน มันจะถูกใช้หมดเสมอ | D15: ⬜ ยังไม่ทำ
... A18: 15 | B18: พอร์ตติดลบเกิน 20% → ห้ามขาย ห้ามหยุด DCA ให้ซื้อต่อตามแผนเดิม | C18: ช่วงที่เจ็บที่สุด คือช่วงที่ราคาถูกที่สุด · แผนเขียนไว้ตอนใจนิ่ง ให้เชื่อแผน ไม่ใช่เชื่อใจตอนตกใจ | D18: ⬜ ยังไม่ทำ

Sheet แผน12เดือน
A1: 🗓️ แผน 12 เดือน — จากวันนี้ถึงเดือนสิงหาคม 2570
A2: ตัวเลขทั้งหมดคำนวณจากแท็บ 'ตั้งค่า' · เป็นประมาณการเพื่อวางแผน ไม่ใช่คำรับประกันผลตอบแทน · ทุกสิ้นเดือน ให้เอาตัวเลขจริงจากแดชบอร์ดไปแก้สมมติฐาน แล้วแผนนี้จะแม่นขึ้นเอง
A3: เดือน | B3: เป้าดีล ที่ต้องโอน | C3: เป้ารายได้ค่าคอม (บาท) | D3: งบโฆษณา (บาท) | E3: ต้นทุนคงที่ (บาท) | F3: กำไรสุทธิคาด (บาท) | G3: เข้าพอร์ต (บาท) | H3: มูลค่าพอร์ตสะสม (บาท) | I3: โฟกัสหลักของเดือนนี้
A4: 46266 | B4: 1 | C4: =ROUND(B4*'ตั้งค่า'!$C$8,0) | D4: =ROUND(MAX('ตั้งค่า'!$C$21,C4*0.15),0) | E4: ='ตั้งค่า'!$C$10 | F4: =C4-D4-E4 | G4: =ROUND(C4*'ตั้งค่า'!$C$36,0) | H4: =ROUND('ตั้งค่า'!$C$28*(1+'ตั้งค่า'!$C$49/12)+G4,0) | I4: ตั้งระบบ: แยกบัญชี 4 ใบ · เริ่มบันทึกทุกวัน · เติมเงินสำรองเป็นอันดับแรก
A5: 46296 | B5: 1 | C5: =ROUND(B5*'ตั้งค่า'!$C$8,0) | D5: =ROUND(MAX('ตั้งค่า'!$C$21,C5*0.15),0) | E5: ='ตั้งค่า'!$C$10 | F5: =C5-D5-E5 | G5: =ROUND(C5*'ตั้งค่า'!$C$36,0) | H5: =ROUND(H4*(1+'ตั้งค่า'!$C$49/12)+G5,0) | I5: หา CPQL จริงของตัวเอง: ทดสอบคอนเทนต์ 3 แบบ วัดผลครบ 30 วัน แล้วแก้สมมติฐาน
A6: 46327 | B6: 2 | C6: =ROUND(B6*'ตั้งค่า'!$C$8,0) | D6: =ROUND(MAX('ตั้งค่า'!$C$21,C6*0.15),0) | E6: ='ตั้งค่า'!$C$10 | F6: =C6-D6-E6 | G6: =ROUND(C6*'ตั้งค่า'!$C$36,0) | H6: =ROUND(H5*(1+'ตั้งค่า'!$C$49/12)+G6,0) | I6: เติม FAQ ใน Google Sheet ของ LINE bot ให้ครบ 50 คำถาม — ลดเวลาตอบ เพิ่มจำนวน lead ที่รับไหว
A7: 46357 | B7: 2 | C7: =ROUND(B7*'ตั้งค่า'!$C$8,0) | D7: =ROUND(MAX('ตั้งค่า'!$C$21,C7*0.15),0) | E7: ='ตั้งค่า'!$C$10 | F7: =C7-D7-E7 | G7: =ROUND(C7*'ตั้งค่า'!$C$36,0) | H7: =ROUND(H6*(1+'ตั้งค่า'!$C$49/12)+G7,0) | I7: เงินสำรองควรเต็มครึ่งทาง · เริ่มซื้อชั้น 1 (พันธบัตร/กองตราสารหนี้)
A8: 46388 | B8: 2 | C8: =ROUND(B8*'ตั้งค่า'!$C$8,0) | D8: =ROUND(MAX('ตั้งค่า'!$C$21,C8*0.15),0) | E8: ='ตั้งค่า'!$C$10 | F8: =C8-D8-E8 | G8: =ROUND(C8*'ตั้งค่า'!$C$36,0) | H8: =ROUND(H7*(1+'ตั้งค่า'!$C$49/12)+G8,0) | I8: เก็บรีวิวลูกค้าจริง 5 ราย ทำเป็นคอนเทนต์ — รีวิวจริงคือสิ่งที่ลด CPQL ได้มากที่สุด
A9: 46419 | B9: 3 | C9: =ROUND(B9*'ตั้งค่า'!$C$8,0) | D9: =ROUND(MAX('ตั้งค่า'!$C$21,C9*0.15),0) | E9: ='ตั้งค่า'!$C$10 | F9: =C9-D9-E9 | G9: =ROUND(C9*'ตั้งค่า'!$C$36,0) | H9: =ROUND(H8*(1+'ตั้งค่า'!$C$49/12)+G9,0) | I9: ทบทวนครึ่งปี: แก้ทุกสมมติฐานด้วยตัวเลขจริง · Rebalance ครั้งที่ 1
A10: 46447 | B10: 3 | C10: =ROUND(B10*'ตั้งค่า'!$C$8,0) | D10: =ROUND(MAX('ตั้งค่า'!$C$21,C10*0.15),0) | E10: ='ตั้งค่า'!$C$10 | F10: =C10-D10-E10 | G10: =ROUND(C10*'ตั้งค่า'!$C$36,0) | H10: =ROUND(H9*(1+'ตั้งค่า'!$C$49/12)+G10,0) | I10: เงินสำรองเต็ม 100% → เริ่มชั้น 2 (หุ้นกู้เรตติ้งดี / REIT)
A11: 46478 | B11: 3 | C11: =ROUND(B11*'ตั้งค่า'!$C$8,0) | D11: =ROUND(MAX('ตั้งค่า'!$C$21,C11*0.15),0) | E11: ='ตั้งค่า'!$C$10 | F11: =C11-D11-E11 | G11: =ROUND(C11*'ตั้งค่า'!$C$36,0) | H11: =ROUND(H10*(1+'ตั้งค่า'!$C$49/12)+G11,0) | I11: ขยายทรัพย์ในมือ: เซ็นสัญญานายหน้ากับเจ้าของบ้าน/โครงการเพิ่มอีก 10 รายการ
A12: 46508 | B12: 4 | C12: =ROUND(B12*'ตั้งค่า'!$C$8,0) | D12: =ROUND(MAX('ตั้งค่า'!$C$21,C12*0.15),0) | E12: ='ตั้งค่า'!$C$10 | F12: =C12-D12-E12 | G12: =ROUND(C12*'ตั้งค่า'!$C$36,0) | H12: =ROUND(H11*(1+'ตั้งค่า'!$C$49/12)+G12,0) | I12: เริ่ม DCA ชั้น 3 (กองดัชนีหุ้นโลก) ทุกวันที่ 1 · ตั้งคำสั่งซื้ออัตโนมัติ จะได้ไม่ต้องใช้ใจ
A13: 46539 | B13: 4 | C13: =ROUND(B13*'ตั้งค่า'!$C$8,0) | D13: =ROUND(MAX('ตั้งค่า'!$C$21,C13*0.15),0) | E13: ='ตั้งค่า'!$C$10 | F13: =C13-D13-E13 | G13: =ROUND(C13*'ตั้งค่า'!$C$36,0) | H13: =ROUND(H12*(1+'ตั้งค่า'!$C$49/12)+G13,0) | I13: หาผู้ช่วยตอบแชท 1 คน — คอขวดของธุรกิจนี้คือเวลาตอบ ไม่ใช่จำนวน lead
A14: 46569 | B14: 4 | C14: =ROUND(B14*'ตั้งค่า'!$C$8,0) | D14: =ROUND(MAX('ตั้งค่า'!$C$21,C14*0.15),0) | E14: ='ตั้งค่า'!$C$10 | F14: =C14-D14-E14 | G14: =ROUND(C14*'ตั้งค่า'!$C$36,0) | H14: =ROUND(H13*(1+'ตั้งค่า'!$C$49/12)+G14,0) | I14: วางแผนภาษีปลายปี: ซื้อกองลดหย่อน (ชั้น 4) ให้เต็มสิทธิ์ก่อน 31 ธ.ค.
A15: 46600 | B15: 5 | C15: =ROUND(B15*'ตั้งค่า'!$C$8,0) | D15: =ROUND(MAX('ตั้งค่า'!$C$21,C15*0.15),0) | E15: ='ตั้งค่า'!$C$10 | F15: =C15-D15-E15 | G15: =ROUND(C15*'ตั้งค่า'!$C$36,0) | H15: =ROUND(H14*(1+'ตั้งค่า'!$C$49/12)+G15,0) | I15: ปิดปี: สรุปตัวเลขจริงทั้งปี · Rebalance ครั้งที่ 2 · ตั้งเป้าปีหน้าจากของจริง ไม่ใช่จากความหวัง
A16: รวม 12 เดือน | B16: =SUM(B4:B15) | C16: =SUM(C4:C15) | D16: =SUM(D4:D15) | E16: =SUM(E4:E15) | F16: =SUM(F4:F15) | G16: =SUM(G4:G15) | H16: =H15 | I16: มูลค่าพอร์ตปลายปีที่ 1 (ประมาณการ)
